{"uuid": "5455e02a-4431-4dd7-afd1-b90d9ce02a55", "children": ["13cdbf53-c2c9-4fcb-9bfa-3ccee2a3be6c"], "befores": [{"name": "xunit_setup_class_fixture_TestAppLogin", "status": "broken", "statusDetails": {"message": "urllib3.exceptions.MaxRetryError: HTTPConnectionPool(host='127.0.0.1', port=4723): Max retries exceeded with url: /wd/hub/session (Caused by NewConnectionError('<urllib3.connection.HTTPConnection object at 0x0000023A58A5AC88>: Failed to establish a new connection: [WinError 10061] 由于目标计算机积极拒绝，无法连接。'))\n", "trace": "  File \"c:\\python\\python37\\lib\\site-packages\\pluggy\\callers.py\", line 187, in _multicall\n    res = hook_impl.function(*args)\n  File \"c:\\python\\python37\\lib\\site-packages\\_pytest\\fixtures.py\", line 1126, in pytest_fixture_setup\n    result = call_fixture_func(fixturefunc, request, kwargs)\n  File \"c:\\python\\python37\\lib\\site-packages\\_pytest\\fixtures.py\", line 925, in call_fixture_func\n    fixture_result = next(generator)\n  File \"c:\\python\\python37\\lib\\site-packages\\_pytest\\python.py\", line 811, in xunit_setup_class_fixture\n    _call_with_optional_argument(func, self.obj)\n  File \"c:\\python\\python37\\lib\\site-packages\\_pytest\\python.py\", line 739, in _call_with_optional_argument\n    func(arg)\n  File \"E:\\unittest_cm03\\uiAutoTestHmtt\\scripts\\test05_app_login.py\", line 15, in setup_class\n    driver = GetDriver.get_app_driver()\n  File \"E:\\unittest_cm03\\uiAutoTestHmtt\\tools\\get_driver.py\", line 59, in get_app_driver\n    cls.__app_driver = appium.webdriver.Remote(\"http://127.0.0.1:4723/wd/hub\", desired_caps)\n  File \"c:\\python\\python37\\lib\\site-packages\\appium\\webdriver\\webdriver.py\", line 129, in __init__\n    proxy\n  File \"c:\\python\\python37\\lib\\site-packages\\selenium\\webdriver\\remote\\webdriver.py\", line 157, in __init__\n    self.start_session(capabilities, browser_profile)\n  File \"c:\\python\\python37\\lib\\site-packages\\appium\\webdriver\\webdriver.py\", line 204, in start_session\n    response = self.execute(RemoteCommand.NEW_SESSION, parameters)\n  File \"c:\\python\\python37\\lib\\site-packages\\selenium\\webdriver\\remote\\webdriver.py\", line 319, in execute\n    response = self.command_executor.execute(driver_command, params)\n  File \"c:\\python\\python37\\lib\\site-packages\\selenium\\webdriver\\remote\\remote_connection.py\", line 374, in execute\n    return self._request(command_info[0], url, body=data)\n  File \"c:\\python\\python37\\lib\\site-packages\\selenium\\webdriver\\remote\\remote_connection.py\", line 402, in _request\n    resp = http.request(method, url, body=body, headers=headers)\n  File \"c:\\python\\python37\\lib\\site-packages\\urllib3\\request.py\", line 72, in request\n    **urlopen_kw)\n  File \"c:\\python\\python37\\lib\\site-packages\\urllib3\\request.py\", line 150, in request_encode_body\n    return self.urlopen(method, url, **extra_kw)\n  File \"c:\\python\\python37\\lib\\site-packages\\urllib3\\poolmanager.py\", line 323, in urlopen\n    response = conn.urlopen(method, u.request_uri, **kw)\n  File \"c:\\python\\python37\\lib\\site-packages\\urllib3\\connectionpool.py\", line 667, in urlopen\n    **response_kw)\n  File \"c:\\python\\python37\\lib\\site-packages\\urllib3\\connectionpool.py\", line 667, in urlopen\n    **response_kw)\n  File \"c:\\python\\python37\\lib\\site-packages\\urllib3\\connectionpool.py\", line 667, in urlopen\n    **response_kw)\n  File \"c:\\python\\python37\\lib\\site-packages\\urllib3\\connectionpool.py\", line 638, in urlopen\n    _stacktrace=sys.exc_info()[2])\n  File \"c:\\python\\python37\\lib\\site-packages\\urllib3\\util\\retry.py\", line 398, in increment\n    raise MaxRetryError(_pool, url, error or ResponseError(cause))\n"}, "start": 1620296182990, "stop": 1620296192057}], "start": 1620296182990, "stop": 1620296192730}